File: RawData1_6/A05D0R_1.csv
System ID,,"4483C1713"
Method name only,,"Tension_Flat_SLOW_DATA_NEW"
Test type,,"Tension"
Sample file name,,"A05D0R"
Last test date,,"Wednesday, April 5, 2023"
Last test time,,"5:59:16 PM"
Course,,"ae461"
Lab Section Number,,"5"
Group,,"D"
Material,,"cf"
Composite Orientation Angle (degrees),,"0"
Crosshead Speed,(mm/min),"4.00"
Geometry,,"Rectangular"
Width,(mm),"23.29"
Thickness,(mm),"2.43"
Specimen Gage Length,(mm),"101.09"
Extensometer Gage Length,(mm),"25.40"
Final Width (mm),,"0.00"
Final Thickness (mm),,"0.00"
Fracture Type and Location,,""
Notes During Test,,""

Results Table 1
,,"1"
Maximum Force,(kN),"42.84"

Time,Displacement,Force,Tensile strain (Strain 1)
(s),(mm),(kN),(mm/mm)
"0.00","0.00","0.04427","-0.00002175"
"0.50","0.03","0.4146","0.00002971"
"1.00","0.07","0.8220","0.0001435"
"1.50","0.10","1.222","0.0002584"
"2.00","0.13","1.614","0.0003710"
"2.50","0.17","1.989","0.0004780"
"3.00","0.20","2.338","0.0005815"
"3.50","0.23","2.653","0.0006833"
"4.00","0.27","2.940","0.0007408"
"4.50","0.30","3.189","0.0008348"
"5.00","0.33","3.370","0.0008754"
"5.50","0.37","3.511","0.0009144"
"6.00","0.40","3.645","0.0009727"
"6.50","0.43","3.797","0.001008"
"7.00","0.47","3.946","0.001054"
"7.50","0.50","4.097","0.001096"
"8.00","0.53","4.245","0.001139"
"8.50","0.57","4.388","0.001174"
"9.00","0.60","4.515","0.001230"
"9.50","0.63","4.651","0.001261"
"10.00","0.67","4.782","0.001295"
"10.50","0.70","4.915","0.001332"
"11.00","0.73","5.030","0.001360"
"11.50","0.77","5.143","0.001399"
"12.00","0.80","5.238","0.001459"
"12.50","0.83","5.352","0.001474"
"13.00","0.87","5.467","0.001495"
"13.50","0.90","5.584","0.001519"
"14.00","0.93","5.691","0.001553"
"14.50","0.97","5.801","0.001592"
"15.00","1.00","5.910","0.001610"
"15.50","1.03","6.018","0.001637"
"16.00","1.07","6.130","0.001670"
"16.50","1.10","6.243","0.001700"
"17.00","1.13","6.357","0.001728"
"17.50","1.17","6.470","0.001769"
"18.00","1.20","6.579","0.001796"
"18.50","1.23","6.691","0.001822"
"19.00","1.27","6.804","0.001858"
"19.50","1.30","6.916","0.001892"
"20.00","1.33","7.026","0.001916"
"20.50","1.37","7.140","0.001949"
"21.00","1.40","7.219","0.002051"
"21.50","1.43","7.346","0.002031"
"22.00","1.47","7.459","0.002050"
"22.50","1.50","7.571","0.002078"
"23.00","1.53","7.687","0.002106"
"23.50","1.57","7.804","0.002142"
"24.00","1.60","7.920","0.002172"
"24.50","1.63","8.035","0.002202"
"25.00","1.67","8.151","0.002236"
"25.50","1.70","8.269","0.002266"
"26.00","1.73","8.387","0.002299"
"26.50","1.77","8.505","0.002333"
"27.00","1.80","8.620","0.002369"
"27.50","1.83","8.740","0.002400"
"28.00","1.87","8.859","0.002430"
"28.50","1.90","8.981","0.002466"
"29.00","1.93","9.101","0.002502"
"29.50","1.97","9.220","0.002531"
"30.00","2.00","9.340","0.002568"
"30.50","2.03","9.461","0.002597"
"31.00","2.07","9.583","0.002638"
"31.50","2.10","9.704","0.002657"
"32.00","2.13","9.824","0.002692"
"32.50","2.17","9.946","0.002723"
"33.00","2.20","10.07","0.002758"
"33.50","2.23","10.19","0.002799"
"34.00","2.27","10.32","0.002823"
"34.50","2.30","10.44","0.002864"
"35.00","2.33","10.57","0.002897"
"35.50","2.37","10.70","0.002937"
"36.00","2.40","10.82","0.002974"
"36.50","2.43","10.95","0.003007"
"37.00","2.47","11.08","0.003040"
"37.50","2.50","11.21","0.003071"
"38.00","2.53","11.33","0.003101"
"38.50","2.57","11.46","0.003137"
"39.00","2.60","11.59","0.003173"
"39.50","2.63","11.72","0.003208"
"40.00","2.67","11.85","0.003237"
"40.50","2.70","11.98","0.003274"
"41.00","2.73","12.12","0.003306"
"41.50","2.77","12.25","0.003344"
"42.00","2.80","12.38","0.003382"
"42.50","2.83","12.52","0.003407"
"43.00","2.87","12.65","0.003453"
"43.50","2.90","12.79","0.003488"
"44.00","2.93","12.92","0.003516"
"44.50","2.97","13.06","0.003562"
"45.00","3.00","13.20","0.003590"
"45.50","3.03","13.33","0.003627"
"46.00","3.07","13.47","0.003661"
"46.50","3.10","13.60","0.003705"
"47.00","3.13","13.74","0.003747"
"47.50","3.17","13.88","0.003790"
"48.00","3.20","14.02","0.003828"
"48.50","3.23","14.16","0.003860"
"49.00","3.27","14.29","0.003906"
"49.50","3.30","14.44","0.003942"
"50.00","3.33","14.58","0.003972"
"50.50","3.37","14.72","0.004006"
"51.00","3.40","14.86","0.004040"
"51.50","3.43","15.01","0.004087"
"52.00","3.47","15.15","0.004112"
"52.50","3.50","15.29","0.004153"
"53.00","3.53","15.44","0.004190"
"53.50","3.57","15.59","0.004221"
"54.00","3.60","15.73","0.004270"
"54.50","3.63","15.87","0.004312"
"55.00","3.67","16.02","0.004348"
"55.50","3.70","16.17","0.004383"
"56.00","3.73","16.31","0.004418"
"56.50","3.77","16.46","0.004461"
"57.00","3.80","16.60","0.004494"
"57.50","3.83","16.75","0.004538"
"58.00","3.87","16.90","0.004575"
"58.50","3.90","17.02","0.004640"
"59.00","3.93","17.12","0.003507"
"59.50","3.97","17.29","0.003525"
"60.00","4.00","17.44","0.003572"
"60.50","4.03","17.59","0.003603"
"61.00","4.07","17.74","0.003639"
"61.50","4.10","17.89","0.003678"
"62.00","4.13","18.04","0.003710"
"62.50","4.17","18.19","0.003753"
"63.00","4.20","18.34","0.003797"
"63.50","4.23","18.49","0.003828"
"64.00","4.27","18.64","0.003874"
"64.50","4.30","18.79","0.003900"
"65.00","4.33","18.94","0.003946"
"65.50","4.37","19.09","0.003981"
"66.00","4.40","19.23","0.004013"
"66.50","4.43","19.37","0.004045"
"67.00","4.47","19.35","0.00005167"
"67.50","4.50","19.58","0.0003145"
"68.00","4.53","19.44","-0.01887"
"68.50","4.57","19.68","-0.01881"
"69.00","4.60","19.85","-0.01877"
"69.50","4.63","20.01","-0.01872"
"70.00","4.67","20.17","-0.01869"
"70.50","4.70","20.34","-0.01863"
"71.00","4.73","20.50","-0.01860"
"71.50","4.77","20.66","-0.01855"
"72.00","4.80","20.83","-0.01851"
"72.50","4.83","20.99","-0.01847"
"73.00","4.87","21.14","-0.01845"
"73.50","4.90","21.31","-0.01841"
"74.00","4.93","21.47","-0.01836"
"74.50","4.97","21.63","-0.01832"
"75.00","5.00","21.79","-0.01828"
"75.50","5.03","21.94","-0.01823"
"76.00","5.07","22.06","-0.01821"
"76.50","5.10","22.17","-0.01817"
"77.00","5.13","22.29","-0.01813"
"77.50","5.17","22.40","-0.01810"
"78.00","5.20","22.52","-0.01806"
"78.50","5.23","22.65","-0.01803"
"79.00","5.27","22.79","-0.01801"
"79.50","5.30","22.93","-0.01797"
"80.00","5.33","23.08","-0.01791"
"80.50","5.37","23.24","-0.01789"
"81.00","5.40","23.39","-0.01784"
"81.50","5.43","23.55","-0.01780"
"82.00","5.47","23.71","-0.01777"
"82.50","5.50","23.87","-0.01773"
"83.00","5.53","24.04","-0.01768"
"83.50","5.57","24.20","-0.01764"
"84.00","5.60","24.36","-0.01759"
"84.50","5.63","24.53","-0.01756"
"85.00","5.67","24.69","-0.01752"
"85.50","5.70","24.86","-0.01750"
"86.00","5.73","25.02","-0.01745"
"86.50","5.77","25.19","-0.01739"
"87.00","5.80","25.35","-0.01736"
"87.50","5.83","25.52","-0.01732"
"88.00","5.87","25.69","-0.01728"
"88.50","5.90","25.85","-0.01724"
"89.00","5.93","26.02","-0.01719"
"89.50","5.97","26.19","-0.01715"
"90.00","6.00","26.35","-0.01711"
"90.50","6.03","26.52","-0.01706"
"91.00","6.07","26.69","-0.01703"
"91.50","6.10","26.86","-0.01698"
"92.00","6.13","26.98","-0.01695"
"92.50","6.17","27.17","-0.01690"
"93.00","6.20","27.34","-0.01686"
"93.50","6.23","27.51","-0.01683"
"94.00","6.27","27.67","-0.01679"
"94.50","6.30","27.84","-0.01675"
"95.00","6.33","28.01","-0.01671"
"95.50","6.37","28.18","-0.01667"
"96.00","6.40","28.35","-0.01662"
"96.50","6.43","28.52","-0.01659"
"97.00","6.47","28.69","-0.01654"
"97.50","6.50","28.86","-0.01650"
"98.00","6.53","29.03","-0.01646"
"98.50","6.57","29.20","-0.01642"
"99.00","6.60","29.37","-0.01639"
"99.50","6.63","29.54","-0.01634"
"100.00","6.67","29.71","-0.01629"
"100.50","6.70","29.88","-0.01626"
"101.00","6.73","30.05","-0.01621"
"101.50","6.77","30.23","-0.01617"
"102.00","6.80","30.39","-0.01613"
"102.50","6.83","30.57","-0.01608"
"103.00","6.87","30.74","-0.01605"
"103.50","6.90","30.91","-0.01600"
"104.00","6.93","31.08","-0.01597"
"104.50","6.97","31.25","-0.01592"
"105.00","7.00","31.42","-0.01588"
"105.50","7.03","31.59","-0.01585"
"106.00","7.07","31.74","-0.01583"
"106.50","7.10","31.92","-0.01578"
"107.00","7.13","32.09","-0.01574"
"107.50","7.17","32.26","-0.01571"
"108.00","7.20","32.43","-0.01567"
"108.50","7.23","32.60","-0.01562"
"109.00","7.27","32.78","-0.01557"
"109.50","7.30","32.94","-0.01554"
"110.00","7.33","33.12","-0.01551"
"110.50","7.37","33.29","-0.01546"
"111.00","7.40","33.46","-0.01542"
"111.50","7.43","33.63","-0.01538"
"112.00","7.47","33.81","-0.01534"
"112.50","7.50","33.98","-0.01528"
"113.00","7.53","34.15","-0.01525"
"113.50","7.57","34.33","-0.01520"
"114.00","7.60","34.50","-0.01516"
"114.50","7.63","34.67","-0.01512"
"115.00","7.67","34.85","-0.01508"
"115.50","7.70","35.02","-0.01504"
"116.00","7.73","35.19","-0.01499"
"116.50","7.77","35.36","-0.01495"
"117.00","7.80","35.53","-0.01492"
"117.50","7.83","35.70","-0.01487"
"118.00","7.87","35.88","-0.01483"
"118.50","7.90","36.05","-0.01478"
"119.00","7.93","36.22","-0.01475"
"119.50","7.97","36.39","-0.01470"
"120.00","8.00","36.56","-0.01466"
"120.50","8.03","36.73","-0.01460"
"121.00","8.07","36.90","-0.01457"
"121.50","8.10","37.07","-0.01453"
"122.00","8.13","37.24","-0.01449"
"122.50","8.17","37.41","-0.01445"
"123.00","8.20","37.59","-0.01441"
"123.50","8.23","37.75","-0.01437"
"124.00","8.27","37.92","-0.01431"
"124.50","8.30","38.09","-0.01429"
"125.00","8.33","38.26","-0.01424"
"125.50","8.37","38.43","-0.01419"
"126.00","8.40","38.59","-0.01416"
"126.50","8.43","38.75","-0.01412"
"127.00","8.47","38.92","-0.01407"
"127.50","8.50","39.08","-0.01404"
"128.00","8.53","39.24","-0.01401"
"128.50","8.57","39.39","-0.01397"
"129.00","8.60","39.55","-0.01393"
"129.50","8.63","39.70","-0.01389"
"130.00","8.67","39.85","-0.01385"
"130.50","8.70","40.00","-0.01381"
"131.00","8.73","40.15","-0.01377"
"131.50","8.77","40.29","-0.01373"
"132.00","8.80","40.43","-0.01371"
"132.50","8.83","40.58","-0.01369"
"133.00","8.87","40.65","-0.01356"
"133.50","8.90","40.66","-0.01379"
"134.00","8.93","40.84","-0.01376"
"134.50","8.97","40.98","-0.01372"
"135.00","9.00","41.07","-0.01368"
"135.50","9.03","41.21","-0.01366"
"136.00","9.07","41.32","-0.01363"
"136.50","9.10","41.43","-0.01360"
"137.00","9.13","41.55","-0.01357"
"137.50","9.17","41.66","-0.01355"
"138.00","9.20","41.77","-0.01351"
"138.50","9.23","41.87","-0.01348"
"139.00","9.27","41.98","-0.01345"
"139.50","9.30","42.08","-0.01342"
"140.00","9.33","42.18","-0.01340"
"140.50","9.37","42.27","-0.01336"
"141.00","9.40","42.37","-0.01334"
"141.50","9.43","42.46","-0.01331"
"142.00","9.47","42.55","-0.01329"
"142.50","9.50","42.64","-0.01325"
"143.00","9.53","42.73","-0.01322"
"143.50","9.57","42.76","-0.01321"
"144.00","9.60","42.78","-0.01319"
"144.50","9.63","42.84","-0.01317"
"145.00","9.67","42.80","-0.01318"
"145.50","9.70","42.71","-0.01319"
"146.00","9.73","42.61","-0.01322"
"146.50","9.77","42.56","-0.01324"
"147.00","9.80","-0.03914","-0.04330"
"147.50","9.83","-0.03496","-0.04329"
"148.00","9.87","-0.03248","-0.04327"
"148.50","9.90","-0.02920","-0.04326"
"149.00","9.93","-0.02792","-0.04325"
"149.50","9.97","-0.02606","-0.04326"
"150.00","10.00","-0.02368","-0.04326"
"150.50","10.03","-0.02251","-0.04324"
"151.00","10.07","-0.02075","-0.04323"
"151.50","10.10","-0.02023","-0.04320"
"152.00","10.13","-0.01931","-0.04321"
"152.50","10.17","-0.01736","-0.04322"
"153.00","10.20","-0.01787","-0.04322"
"153.50","10.23","-0.01782","-0.04321"
"154.00","10.27","-0.01614","-0.04321"
"154.50","10.30","-0.01580","-0.04322"
"155.00","10.33","-0.01589","-0.04321"
"155.50","10.37","-0.01499","-0.04322"
"156.00","10.40","-0.01463","-0.04321"
"156.50","10.43","-0.01489","-0.04321"
"157.00","10.47","-0.01441","-0.04320"
"157.50","10.50","-0.01327","-0.04322"
"158.00","10.53","-0.01396","-0.04321"
"158.50","10.57","-0.01311","-0.04322"
"158.96","10.60","-0.01293","-0.04322"